Workbook

Sheet JUNGER
A1: BẢNG MÃ HÀNG HÓA 2025
A2: Mã vật tư | B2: Tên vật tư | C2: Nhóm v.tư 1 | D2: Nhóm v.tư 3
B3: BẾP ĐƠN
A4: ASC-86 | B4: Bếp đơn hồng ngoại ASC-86 | C4: BEPDON | D4: JUNGER
A5: CEJ-105-I | B5: Bếp từ đơn Junger CEJ-105-I | C5: BEPDON | D5: JUNGER
A6: IS-19 | B6: Bếp đơn hồng ngoại IS_19 | C6: BEPDON | D6: JUNGER
A7: MT-92 | B7: Bếp đơn hồng ngoại MT_92 | C7: BEPDON | D7: JUNGER
A8: CEJ-106-I | B8: Bếp từ đơn Junger CEJ-106-I | C8: BEPDON | D8: JUNGER | E8: BỎ MÃ
A9: IS-20 | B9: Bếp điện từ đơn, Junger, IS_20 | C9: BEPDON | D9: JUNGER | E9: BỎ MÃ
A10: IS-22 | B10: Bếp điện từ đơn, Junger, IS_22 | C10: BEPDON | D10: JUNGER | E10: BỎ MÃ
A11: MT-21 | B11: Bếp đơn hồng ngoại MT_21 | C11: BEPDON | D11: JUNGER | E11: CHƯA CHÀO VÀO LẠI CHỢ LỚN NÊN KHẢ NĂNG KHÔNG CHÀO LẠI ĐƯỢC THÌ PHẢI CLEAR
B12: BẾP ĐÔI
A13: CEJ-200-II | B13: Bếp điện từ đôi Junger CEJ-200-II | C13: BEPDOI | D13: JUNGER
A14: CEJ-201-II | B14: Bếp điện từ đôi Junger CEJ-201-II | C14: BEPDOI | D14: JUNGER
A15: CEJ-202-II | B15: Bếp điện từ đôi Junger CEJ-202-II | C15: BEPDOI | D15: JUNGER
A16: CEJ-203-IF | B16: Bếp điện đôi junger CEJ-203-IF | C16: BEPDOI | D16: JUNGER
A17: CEJ-220-INVERTER | B17: Bếp điện từ đôi Junger CEJ-220-INVERTER | C17: BEPDOI | D17: JUNGER | E17: MÃ MỚI
A18: CEJ-221-INVERTER | B18: Bếp điện từ đôi Junger CEJ-221-INVERTER | C18: BEPDOI | D18: JUNGER | E18: MÃ MỚI
A19: CEJ-222-INVERTER | B19: Bếp điện từ đôi Junger CEJ-222-INVERTER | C19: BEPDOI | D19: JUNGER | E19: MÃ MỚI
A20: CEJ-225-INVERTER | B20: Bếp điện từ đôi Junger CEJ-225-INVERTER | C20: BEPDOI | D20: JUNGER | E20: MÃ MỚI
A21: CEJ-226-INVERTER | B21: Bếp điện từ đôi Junger CEJ-226-INVERTER | C21: BEPDOI | D21: JUNGER | E21: MÃ MỚI
A22: SIS-66 | B22: Bếp đôi từ và nhiệt SIS_66 | C22: BEPDOI | D22: JUNGER
A23: SIS-68 | B23: Bếp đôi từ và nhiệt SIS_68 | C23: BEPDOI | D23: JUNGER
A24: ID-16 | B24: Bếp đôi từ và nhiệt ID-16 | C24: BEPDOI | D24: JUNGER
A25: ID-39 | B25: Bếp điện đôi Junger ID-39 | C25: BEPDOI | D25: JUNGER
A26: MK-22 | B26: Bếp điện từ đôi, Junger, MK-22 | C26: BEPDOI | D26: JUNGER
A27: MK-24 | B27: Bếp điện hồng ngoại đôi, Junger, MK-24 | C27: BEPDOI | D27: JUNGER
A28: MTD-18 | B28: Bếp đôi Junger MTD - 18 | C28: BEPDOI | D28: JUNGER
A29: MTD-71 | B29: Bếp đôi Junger MTD - 71 | C29: BEPDOI | D29: JUNGER
A30: NKD22+ | B30: Bếp điện từ đôi, Junger, NKD22+ | C30: BEPDOI | D30: JUNGER
A31: CEJ-204-IF | B31: Bếp điện đôi junger CEJ-204-IF | C31: BEPDOI | D31: JUNGER | E31: BỎ MÃ
A32: CEJ-300-IIF | B32: Bếp điện từ ba Junger CEJ-300-IIF | C32: BEPBA | D32: JUNGER | E32: BỎ MÃ
A33: ID-18 | B33: Bếp đôi từ và nhiệt ID_18 | C33: BEPDOI | D33: JUNGER | E33: BỎ MÃ
A34: NKD-20 | B34: Bếp đôi Junger NKD - 20 | C34: BEPDOI | D34: JUNGER | E34: BỎ MÃ
B35: BỘ NỒI
A36: CWJ-070 | B36: Bộ nồi inox Junger CWJ_070 | C36: NOI | D36: JUNGER
A37: JC-100 | B37: Bộ nồi Inox nắp kính hiệu Junger(13 món) | C37: NOI | D37: JUNGER
A38: CWJ-050 | B38: Bộ nồi inox Junger CWJ_050 | C38: NOI | D38: JUNGER | E38: BỎ MÃ
A39: JC-200 | B39: Bộ nồi inox 7 chi tiết, Junger, JC200 | C39: NOI | D39: JUNGER | E39: BỎ MÃ
B40: HÚT MÙI
...

Sheet HWK
A1: BẢNG MÃ HÀNG HÓA 2025
A2: Mã vật tư | B2: Tên vật tư | C2: Nhóm v.tư 1 | D2: Nhóm v.tư 3
B3: NỒI CHIÊN KHÔNG DẦU
A4: AFH-045 | B4: Nồi chiên không dầu Hawonkoo AFH-045 | C4: NOICHIEN | D4: HAWONKOO | E4: BỎ MÃ
A5: AFH-100 | B5: Nồi chiên không dầu HAWONKOO AFH-100 | C5: NOICHIEN | D5: HAWONKOO | E5: BỎ MÃ
A6: AFH-100-TQ | B6: Nồi chiên không dầu HAWONKOO AFH-100 | C6: NOICHIEN | D6: HAWONKOO | E6: BỎ MÃ
A7: AFH-101-TQ | B7: Nồi chiên không dầu HAWONKOO AFH-101 | C7: NOICHIEN | D7: HAWONKOO | E7: BỎ MÃ
A8: AFH-101 | B8: Nồi chiên không dầu HAWONKOO AFH-101 | C8: NOICHIEN | D8: HAWONKOO | E8: BỎ MÃ
A9: AFH-120-BA | B9: Nồi chiên không dầu HAWONKOO AFH-120-BA | C9: NOICHIEN | D9: HAWONKOO | E9: BỎ MÃ
A10: AFH-120-CF | B10: Nồi chiên không dầu HAWONKOO AFH-120-CF | C10: NOICHIEN | D10: HAWONKOO | E10: BỎ MÃ
A11: AFH-120-GR | B11: Nồi chiên không dầu Hawonkoo AFH-120-GR | C11: NOICHIEN | D11: HAWONKOO | E11: BỎ MÃ
A12: AFH-120-W | B12: Nồi chiên không dầu HAWONKOO AFH-120-W | C12: NOICHIEN | D12: HAWONKOO | E12: BỎ MÃ
A13: AFH-128-W | B13: Nồi chiên không dầu HAWONKOO AFH-128-W | C13: NOICHIEN | D13: HAWONKOO | E13: BỎ MÃ
A14: AFH-180-PK | B14: Nồi chiên không dầu HAWONKOO AFH-180-PK | C14: NOICHIEN | D14: HAWONKOO | E14: BỎ MÃ
A15: AFH-180-CF | B15: Nồi chiên không dầu HAWONKOO AFH-180-CF | C15: NOICHIEN | D15: HAWONKOO
A16: AFH-180-GR | B16: Nồi chiên không dầu HAWONKOO AFH-180-GR | C16: NOICHIEN | D16: HAWONKOO
B17: BẾP ĐƠN-LẨU
A18: CEH-107-BA | B18: Bếp điện từ đơn kèm nồi 2 chi tiết Hawonkoo CEH-107-BA | C18: BEPDON | D18: HAWONKOO
A19: CEH-101-I-CF | B19: Bếp điện từ đơn Hawonkoo CEH-101-I-CF | C19: BEPDON | D19: HAWONKOO
A20: CEH-101-I-GR | B20: Bếp điện từ đơn Hawonkoo CEH-101-I-GR | C20: BEPDON | D20: HAWONKOO
A21: CWH-001-CF | B21: Nồi lẩu Hawonkoo CWH-001-CF | C21: NOILAU | D21: HAWONKOO
A22: CWH-001-GR | B22: Nồi lẩu Hawonkoo CWH-001-GR | C22: NOILAU | D22: HAWONKOO
A23: CEH-106-GR | B23: Bếp từ đơn kèm nồi 2 chi tiết Hawonkoo SEOUL-CEH-106 INVERTER-GR | C23: BEPDON | D23: HAWONKOO | E23: MÃ MỚI
A24: CEH-106-CF | B24: Bếp từ đơn kèm nồi 2 chi tiết Hawonkoo SEOUL-CEH-106 INVERTER-CF | C24: BEPDON | D24: HAWONKOO | E24: MÃ MỚI
A25: CEH-108-GR | B25: Bếp từ đơn kèm nồi 2 chi tiết Hawonkoo SEOUL-CEH-108 INVERTER-GR | C25: BEPDON | D25: HAWONKOO | E25: MÃ MỚI
A26: CEH-108-CF | B26: Bếp từ đơn kèm nồi 2 chi tiết Hawonkoo SEOUL-CEH-108 INVERTER-CF | C26: BEPDON | D26: HAWONKOO | E26: MÃ MỚI
A27: CEH-109-I | B27: Bếp từ đơn Hawonkoo SEOUL-CEH-109 INVERTER-I | C27: BEPDON | D27: HAWONKOO | E27: MÃ MỚI
A28: CEH-101-I-PK | B28: Bếp điện từ đơn Hawonkoo CEH-101-I-PK | C28: BEPDON | D28: HAWONKOO | E28: BỎ MÃ
A29: CWH-001-W | B29: Nồi lẩu Hawonkoo CWH-001-W | C29: NOILAU | D29: HAWONKOO | E29: BỎ MÃ
A30: CWH-001-PK | B30: Nồi lẩu Hawonkoo CWH-001-PK | C30: NOILAU | D30: HAWONKOO | E30: BỎ MÃ
A31: HEH-100-GE | B31: Nồi lẩu điện Hawonkoo HEH-100-GE | C31: NOILAU | D31: HAWONKOO | E31: BỎ MÃ
A32: HEH-100-PK | B32: Nồi lẩu điện Hawonkoo HEH-100-PK | C32: NOILAU | D32: HAWONKOO | E32: BỎ MÃ
A33: MCEH-200-II-CF | B33: Bếp từ đôi kèm bộ nồi 05 chi tiết Hawonkoo MCEH-200-II-CF | C33: BEPDOI | D33: HAWONKOO | E33: BỎ MÃ
A34: MCEH-200-II-GE | B34: Bếp từ đôi kèm bộ nồi 05 chi tiết Hawonkoo MCEH-200-II-GE | C34: BEPDOI | D34: HAWONKOO | E34: BỎ MÃ
A35: MCEH-200-II-GR | B35: Bếp từ đôi kèm bộ nồi 05 chi tiết Hawonkoo MCEH-200-II-GR | C35: BEPDOI | D35: HAWONKOO | E35: BỎ MÃ
B36: BẾP ĐÔI
A37: CEH-201-IF | B37: Bếp đôi 1 từ 1 hồng ngoại Hawonkoo CEH-201-IF | C37: BEPDOI | D37: HAWONKOO | E37: BỎ MÃ
A38: CEH-202-II | B38: Bếp điện từ đôi Hawonkoo CEH-202-II | C38: BEPDOI | D38: HAWONKOO | E38: BỎ MÃ
A39: CEH-204-IF | B39: Bếp đôi 1 từ 1 hồng ngoại Hawonkoo CEH-204-IF | C39: BEPDOI | D39: HAWONKOO | E39: BỎ MÃ
A40: CEH-205-II | B40: Bếp điện từ đôi Hawonkoo CEH-205-II | C40: BEPDOI | D40: HAWONKOO | E40: BỎ MÃ
...

Sheet CSSK
A1: BẢNG GIÁ VỐN NGÀNH HÀNG CSSK
A2: Mã vật tư | B2: Mã vật tư mã cũ | C2: Tên vật tư | D2: ĐƠN GIÁ | E2: ĐƠN GIÁ VỐN (+VAT) | F2: Nhóm v.tư 1 | G2: Nhóm v.tư 3 | H2: GIÁ MIN | J2: von
A3: BEP-668-IRIS-04 | B3: BEP_668_IRIS_04 | C3: Xe đạp tập thể dục Poongsan BEP-668 - IRIS -04 | D3: 2317890 | E3: =D3*1.1 -> 2549679 | F3: XEDAP | G3: MASSAGE | H3: 4990000 | J3: =ROUND(VLOOKUP(A3,#REF!,6,0),0) -> #REF! | K3: =ROUND(VLOOKUP(A3,#REF!,7,0),0) -> #REF!
A4: BEP-670-IRIS-05 | B4: BEP_670_IRIS_05 | C4: Xe đạp tập thể dục Poongsan BEP-670 - IRIS -05 | D4: 2802349 | E4: =D4*1.1 -> 3082583.9 | F4: XEDAP | G4: MASSAGE | H4: 4990000 | J4: =ROUND(VLOOKUP(A4,#REF!,6,0),0) -> #REF! | K4: =ROUND(VLOOKUP(A4,#REF!,7,0),0) -> #REF!
A5: BEP-700-IRIS-03 | B5: BEP_700_IRIS_03 | C5: Xe đạp tập thể dục Poongsan BEP -700 - IRIS -03 | D5: 4052320 | E5: =D5*1.1 -> 4457552 | F5: XEDAP | G5: MASSAGE | H5: 7090000 | J5: =ROUND(VLOOKUP(A5,#REF!,6,0),0) -> #REF! | K5: =ROUND(VLOOKUP(A5,#REF!,7,0),0) -> #REF!
A6: DMJ-189 | B6: DMJ_189 | C6: Ghế massage Boss DMJ-189 | D6: 8830812 | E6: =D6*1.1 -> 9713893.2 | F6: GHE | G6: MASSAGE | H6: 35000000 | J6: =ROUND(VLOOKUP(A6,#REF!,6,0),0) -> #REF! | K6: =ROUND(VLOOKUP(A6,#REF!,7,0),0) -> #REF!
A7: DMJ-195 | B7: DMJ_195 | C7: Máy Massage dạng ghế, Boss, DMJ_195 | D7: 17100318 | E7: =D7*1.1 -> 18810350 | F7: GHE | G7: MASSAGE | H7: 30000000 | J7: =ROUND(VLOOKUP(A7,#REF!,6,0),0) -> #REF! | K7: =ROUND(VLOOKUP(A7,#REF!,7,0),0) -> #REF!
A8: DMJ-197 | B8: DMJ_197 | C8: Máy massage dạng ghế, BOSS, DMJ-197 | D8: 19038098 | E8: =D8*1.1 -> 20941908 | F8: GHE | G8: MASSAGE | H8: 49500000 | J8: =ROUND(VLOOKUP(A8,#REF!,6,0),0) -> #REF! | K8: =ROUND(VLOOKUP(A8,#REF!,7,0),0) -> #REF!
A9: DMJ-200 | B9: DMJ_200 | C9: Máy massage dạng ghế DMJ_200 | D9: 23256681 | E9: =D9*1.1 -> 25582349 | F9: GHE | G9: MASSAGE | H9: 70000000 | J9: =ROUND(VLOOKUP(A9,#REF!,6,0),0) -> #REF! | K9: =ROUND(VLOOKUP(A9,#REF!,7,0),0) -> #REF!
A10: DMJ-202 | B10: DMJ_202 | C10: Máy massage dạng ghế DMJ_202 | D10: 31143710 | E10: =D10*1.1 -> 34258081 | F10: GHE | G10: MASSAGE | H10: 85000000 | J10: =ROUND(VLOOKUP(A10,#REF!,6,0),0) -> #REF! | K10: =ROUND(VLOOKUP(A10,#REF!,7,0),0) -> #REF!
A11: DMK-166 | B11: DMK_166 | C11: Máy Massage dạng ghế DMK166 | D11: 15543652 | E11: =D11*1.1 -> 17098017 | F11: GHE | G11: MASSAGE | H11: 8000000 | J11: =ROUND(VLOOKUP(A11,#REF!,6,0),0) -> #REF! | K11: =ROUND(VLOOKUP(A11,#REF!,7,0),0) -> #REF!
A12: DMK-168 | B12: DMK_168 | C12: Máy Massage dạng ghế DMK168 | D12: 15431347 | E12: =D12*1.1 -> 16974482 | F12: GHE | G12: MASSAGE | H12: 25000000 | J12: =ROUND(VLOOKUP(A12,#REF!,6,0),0) -> #REF! | K12: =ROUND(VLOOKUP(A12,#REF!,7,0),0) -> #REF!
A13: DMK-191 | B13: DMK_191 | C13: Máy massage dạng ghế,Poongsan, DMK_191 | D13: 19080837 | E13: =D13*1.1 -> 20988921 | F13: GHE | G13: MASSAGE | H13: 32000000 | J13: =ROUND(VLOOKUP(A13,#REF!,6,0),0) -> #REF! | K13: =ROUND(VLOOKUP(A13,#REF!,7,0),0) -> #REF!
A14: EMJ-966 | B14: EMJ_966 | C14: Đệm Massage Boss EMJ_966 | D14: 2008405 | E14: =D14*1.1 -> 2209245.5 | F14: DEM | G14: MASSAGE | H14: 32000000 | J14: =ROUND(VLOOKUP(A14,#REF!,6,0),0) -> #REF! | K14: =ROUND(VLOOKUP(A14,#REF!,7,0),0) -> #REF!
... A51: MCP-300-C | B51: MCP_300_C | C51: Ghế Massage Poongsan MCP-300-C | D51: 13659512 | E51: =D51*1.1 -> 15025463 | F51: GHE | G51: MASSAGE | H51: 37990000 | J51: =ROUND(VLOOKUP(A51,#REF!,6,0),0) -> #REF! | K51: =ROUND(VLOOKUP(A51,#REF!,7,0),0) -> #REF!
A52: MCP-302-GR | B52: MCP_302_GR | C52: Ghế massage, Poongsan, MCP-302-GR | D52: 13985031 | E52: =D52*1.1 -> 15383534 | F52: GHE | G52: MASSAGE | J52: =ROUND(VLOOKUP(A52,#REF!,6,0),0) -> #REF! | K52: =ROUND(VLOOKUP(A52,#REF!,7,0),0) -> #REF!
A53: MCP-302-YE | B53: MCP_302_YE | C53: Ghế massage, Poongsan, MCP-302-YE | D53: 14038177 | E53: =D53*1.1 -> 15441995 | F53: GHE | G53: MASSAGE | H53: 0 | J53: =ROUND(VLOOKUP(A53,#REF!,6,0),0) -> #REF! | K53: =ROUND(VLOOKUP(A53,#REF!,7,0),0) -> #REF!
A54: MCP-303-BR | B54: MCP_303_BR | C54: Ghế Massage Poongsan MCP-303-BR | D54: 13293157 | E54: =D54*1.1 -> 14622473 | F54: GHE | G54: MASSAGE | H54: 45000000 | J54: =ROUND(VLOOKUP(A54,#REF!,6,0),0) -> #REF! | K54: =ROUND(VLOOKUP(A54,#REF!,7,0),0) -> #REF!
A55: MCP-303-GR | B55: MCP_303_GR | C55: Ghế Massage Poongsan MCP-303-GR | D55: 13358919 | E55: =D55*1.1 -> 14694811 | F55: GHE | G55: MASSAGE | H55: 45000000 | J55: =ROUND(VLOOKUP(A55,#REF!,6,0),0) -> #REF! | K55: =ROUND(VLOOKUP(A55,#REF!,7,0),0) -> #REF!
A56: MCP-500-ATLAS | B56: MCP_500_ATLAS | C56: Ghế Massage Poongsan MCP-500-ATLAS | D56: 17228874 | E56: =D56*1.1 -> 18951761 | F56: GHE | G56: MASSAGE | H56: 0 | J56: =ROUND(VLOOKUP(A56,#REF!,6,0),0) -> #REF! | K56: =ROUND(VLOOKUP(A56,#REF!,7,0),0) -> #REF!
A57: MCP-501-BR | B57: MCP_501_BR | C57: Ghế Massage Poongsan MCP-501-BR | D57: 16540071 | E57: =D57*1.1 -> 18194078 | F57: GHE | G57: MASSAGE | H57: 53990000 | J57: =ROUND(VLOOKUP(A57,#REF!,6,0),0) -> #REF! | K57: =ROUND(VLOOKUP(A57,#REF!,7,0),0) -> #REF!
A58: MCP-501-RE | B58: MCP_501_RE | C58: Ghế Massage Poongsan MCP-501-RE | D58: 17786337 | E58: =D58*1.1 -> 19564971 | F58: GHE | G58: MASSAGE | H58: 55000000 | J58: =ROUND(VLOOKUP(A58,#REF!,6,0),0) -> #REF! | K58: =ROUND(VLOOKUP(A58,#REF!,7,0),0) -> #REF!
A59: MCP-502-BE | B59: MCP_502_BE | C59: Ghế Massage Poongsan MCP-502-BE | D59: 17642901 | E59: =D59*1.1 -> 19407191 | F59: GHE | G59: MASSAGE | H59: 29990000 | J59: =ROUND(VLOOKUP(A59,#REF!,6,0),0) -> #REF! | K59: =ROUND(VLOOKUP(A59,#REF!,7,0),0) -> #REF!
A60: MCP-502-BL | B60: MCP_502_BL | C60: Ghế Massage Poongsan MCP-502-BL | D60: 17644114 | E60: =D60*1.1 -> 19408525 | F60: GHE | G60: MASSAGE | H60: 29990000 | J60: =ROUND(VLOOKUP(A60,#REF!,6,0),0) -> #REF! | K60: =ROUND(VLOOKUP(A60,#REF!,7,0),0) -> #REF!
A61: MCP-804-BL | B61: MCP_804_BL | C61: Ghế Massage Poongsan MCP_804_BL | D61: 19531238 | E61: =D61*1.1 -> 21484362 | F61: GHE | G61: MASSAGE | H61: 59990000 | J61: =ROUND(VLOOKUP(A61,#REF!,6,0),0) -> #REF! | K61: =ROUND(VLOOKUP(A61,#REF!,7,0),0) -> #REF!
A62: MCP-804-GR | B62: MCP_804_GR | C62: Ghế Massage Poongsan MCP_804_GR | D62: 19484790 | E62: =D62*1.1 -> 21433269 | F62: GHE | G62: MASSAGE | H62: 59990000 | J62: =ROUND(VLOOKUP(A62,#REF!,6,0),0) -> #REF! | K62: =ROUND(VLOOKUP(A62,#REF!,7,0),0) -> #REF!
A63: MCP-805 | B63: MCP_805 | C63: Ghế Massage Poongsan MCP_805 | D63: 21939336 | E63: =D63*1.1 -> 24133270 | F63: GHE | G63: MASSAGE | H63: 53990000 | J63: =ROUND(VLOOKUP(A63,#REF!,6,0),0) -> #REF! | K63: =ROUND(VLOOKUP(A63,#REF!,7,0),0) -> #REF!
A64: MCP-806-BA | B64: MCP_806_BA | C64: Ghế Massage Poongsan MCP_806_BA | D64: 25244574 | E64: =D64*1.1 -> 27769031 | F64: GHE | G64: MASSAGE | H64: 85000000 | J64: =ROUND(VLOOKUP(A64,#REF!,6,0),0) -> #REF! | K64: =ROUND(VLOOKUP(A64,#REF!,7,0),0) -> #REF!
... A85: PS-06 | B85: PS_06 | C85: Máy Massage chân Poongsan PS_06 | D85: 2272552 | E85: =D85*1.1 -> 2499807.2 | F85: CHAN | G85: MASSAGE | H85: 4000000 | J85: =ROUND(VLOOKUP(A85,#REF!,6,0),0) -> #REF! | K85: =ROUND(VLOOKUP(A85,#REF!,7,0),0) -> #REF!
A86: PS_20 | B86: PS_20 | C86: Gối Massage, Poongsan, PS-20 | D86: 665884 | E86: =D86*1.1 -> 732472.4 | F86: GOI | G86: MASSAGE | J86: =ROUND(VLOOKUP(A86,#REF!,6,0),0) -> #REF! | K86: =ROUND(VLOOKUP(A86,#REF!,7,0),0) -> #REF!
A87: PS-25 | B87: PS_25 | C87: Máy Massage dạng cầm tay,Poongsan,PS-25 | D87: 412302 | E87: =D87*1.1 -> 453532.2 | F87: TAY | G87: MASSAGE | J87: =ROUND(VLOOKUP(A87,#REF!,6,0),0) -> #REF! | K87: =ROUND(VLOOKUP(A87,#REF!,7,0),0) -> #REF!
A88: PS986 | B88: PS986 | C88: Đệm Massage Poongsan PS 986 | D88: 901087 | E88: =D88*1.1 -> 991195.7 | F88: DEM | G88: MASSAGE | H88: 0 | J88: =ROUND(VLOOKUP(A88,#REF!,6,0),0) -> #REF! | K88: =ROUND(VLOOKUP(A88,#REF!,7,0),0) -> #REF!
A89: PS999B | B89: PS999B | C89: Máy Massage tay PS 999B | D89: 340999 | E89: =D89*1.1 -> 375098.9 | F89: TAY | G89: MASSAGE | H89: 0 | J89: =ROUND(VLOOKUP(A89,#REF!,6,0),0) -> #REF! | K89: =ROUND(VLOOKUP(A89,#REF!,7,0),0) -> #REF!
A90: SMK_669 | B90: SMK_669 | C90: Máy Massage tay Poongsan SMK 669 | D90: 314815 | E90: =D90*1.1 -> 346296.5 | F90: TAY | G90: MASSAGE | H90: 0 | J90: =ROUND(VLOOKUP(A90,#REF!,6,0),0) -> #REF! | K90: =ROUND(VLOOKUP(A90,#REF!,7,0),0) -> #REF!
A91: TMP-250 | B91: TMP_250 | C91: Máy luyện tập thể chất kiểu chạy bộ Poongsan TMP_250 | D91: 4328756 | E91: =D91*1.1 -> 4761631.6 | F91: CHAYBO | G91: MASSAGE | H91: 7990000 | J91: =ROUND(VLOOKUP(A91,#REF!,6,0),0) -> #REF! | K91: =ROUND(VLOOKUP(A91,#REF!,7,0),0) -> #REF!
A92: TMP-850 | B92: TMP_850 | C92: Máy luyện tập thể chất kiểu chạy bộ Poongsan TMP_850 | D92: 5856554 | E92: =D92*1.1 -> 6442209.4 | F92: CHAYBO | G92: MASSAGE | H92: 18990000 | J92: =ROUND(VLOOKUP(A92,#REF!,6,0),0) -> #REF! | K92: =ROUND(VLOOKUP(A92,#REF!,7,0),0) -> #REF!
A93: TMP-888-ATHENA-01 | B93: TMP_888 | C93: Máy chạy bộ Poongsan TMP-888-ATHENA-01 | D93: 8866190 | E93: =D93*1.1 -> 9752809 | F93: CHAYBO | G93: MASSAGE | H93: 22000000 | J93: =ROUND(VLOOKUP(A93,#REF!,6,0),0) -> #REF! | K93: =ROUND(VLOOKUP(A93,#REF!,7,0),0) -> #REF!
A94: TMP-889-ATHENA-02 | B94: TMP_889 | C94: Máy chạy bộ Poongsan TMP-889-ATHENA-02 | D94: 6384243 | E94: =D94*1.1 -> 7022667.3 | F94: CHAYBO | G94: MASSAGE | H94: 12990000 | J94: =ROUND(VLOOKUP(A94,#REF!,6,0),0) -> #REF! | K94: =ROUND(VLOOKUP(A94,#REF!,7,0),0) -> #REF!
A95: TMP-900-ATHENA-03 | B95: TMP_900 | C95: Máy chạy bộ Poongsan TMP-900-ATHENA-03 | D95: 5519059 | E95: =D95*1.1 -> 6070964.9 | F95: CHAYBO | G95: MASSAGE | H95: 9990000 | J95: =ROUND(VLOOKUP(A95,#REF!,6,0),0) -> #REF! | K95: =ROUND(VLOOKUP(A95,#REF!,7,0),0) -> #REF!
A96: MCP-130 | B96: MCP_130 | C96: Ghế Massage Poongsan MCP-130 | D96: 9984809 | E96: =D96*1.1 -> 10983290 | F96: GHE | H96: 15990000 | J96: =ROUND(VLOOKUP(A96,#REF!,6,0),0) -> #REF! | K96: =ROUND(VLOOKUP(A96,#REF!,7,0),0) -> #REF!
...

Sheet BOSS
A1: BẢNG MÃ HÀNG HÓA 2025
A2: Mã vật tư | B2: Tên vật tư | C2: Nhóm v.tư 1 | D2: Nhóm v.tư 3
A3: FEAB-110 | B3: Quạt làm mát không khí, Boss, FEAB-110 | C3: QUATBOS | D3: QUATBOSS
A4: S102 | B4: Máy làm mát không khí bằng bay hơi, Boss, S102 | C4: QUATBOS | D4: QUATBOSS
A5: S106 | B5: Máy làm mát không khí bằng bay hơi, Boss, S106 | C5: QUATBOS | D5: QUATBOSS
A6: S105 | B6: Máy làm mát không khí bằng bay hơi, Boss, S105 | C6: QUATBOS
A7: BOSS-88-BLDC-INVERTER | B7: Quạt điện (cây) Boss BOSS-88-BLDC-INVERTER | E7: Mã mới
A8: FEAB-407-G | B8: Quạt làm mát không khí, Boss, FEAB-407-G | C8: QUATBOS | D8: QUATBOSS | E8: Bỏ mã
A9: FEAB-409-G | B9: Quạt làm mát không khí, Boss, FEAB-409-G | C9: QUATBOS | D9: QUATBOSS | E9: Bỏ mã
A10: FEAB-705-W | B10: Quạt làm mát không khí, Boss, FEAB-705-W | C10: QUATBOS | D10: QUATBOSS | E10: Bỏ mã
A11: JF-96 | B11: Quạt phun sương JF_96 | C11: QUATBOS | D11: QUATBOSS | E11: Bỏ mã
A12: JF-98 | B12: Quạt phun sương JF_98 | C12: QUATBOS | D12: QUATBOSS | E12: Bỏ mã
A13: S101 | B13: Máy làm mát không khí bằng bay hơi, Boss, S101 | C13: QUATBOS | D13: QUATBOSS | E13: Bỏ mã
A14: QJ12F1 | B14: Quạt cơ SF - J12F1 | C14: QUATCO | D14: QUATBOSS | E14: Bỏ mã

Sheet GIÁ VON T12
A1: Mã kho | B1: Tên kho | C1: Mã vật tư | D1: Tên vật tư | E1: Đvt | F1: Giá | H1: bep | I1: ha | J1: ms | K1: bos
A2: 02CMTK02 | B2: Kho Mới Tô Ký - Xóm Chợ -Bếp+Khác | C2: DWJ_101 | D2: Máy rửa bát đĩa 6 bộ Junger DWJ-101 | E2: chiếc | F2: 3302503.8 | H2: =VLOOKUP(C2,JUNGER!$A$3:$B$7785,1,0) -> #N/A | I2: =VLOOKUP(C2,HWK!$A$3:$B$8917,1,0) -> #N/A | J2: =VLOOKUP(C2,CSSK!$A$3:$D$9887,1,0) -> #N/A | K2: =VLOOKUP(C2,BOSS!$A$3:$B$1212,1,0) -> #N/A
A3: 02CMTK02 | B3: Kho Mới Tô Ký - Xóm Chợ -Bếp+Khác | C3: DWJ_600 | D3: Máy rửa bát đĩa 14 bộ Junger DWJ-600 | E3: chiếc | F3: 5492159.8 | H3: =VLOOKUP(C3,JUNGER!$A$3:$B$7785,1,0) -> #N/A | I3: =VLOOKUP(C3,HWK!$A$3:$B$8917,1,0) -> #N/A | J3: =VLOOKUP(C3,CSSK!$A$3:$D$9887,1,0) -> #N/A | K3: =VLOOKUP(C3,BOSS!$A$3:$B$1212,1,0) -> #N/A
A4: 02CMTK04 | B4: Kho Mới Tô Ký - Xóm Chợ - Hawonkoo | C4: AFH_101_TQ | D4: Nồi chiên không dầu HAWONKOO AFH-101 | E4: chiếc | F4: 1117603 | H4: =VLOOKUP(C4,JUNGER!$A$3:$B$7785,1,0) -> #N/A | I4: =VLOOKUP(C4,HWK!$A$3:$B$8917,1,0) -> #N/A | J4: =VLOOKUP(C4,CSSK!$A$3:$D$9887,1,0) -> #N/A | K4: =VLOOKUP(C4,BOSS!$A$3:$B$1212,1,0) -> #N/A
A5: 02CMTK04 | B5: Kho Mới Tô Ký - Xóm Chợ - Hawonkoo | C5: CEH_205_II | D5: Bếp điện từ đôi Hawonkoo CEH-205-II | E5: chiếc | F5: 1870680.2 | H5: =VLOOKUP(C5,JUNGER!$A$3:$B$7785,1,0) -> #N/A | I5: =VLOOKUP(C5,HWK!$A$3:$B$8917,1,0) -> #N/A | J5: =VLOOKUP(C5,CSSK!$A$3:$D$9887,1,0) -> #N/A | K5: =VLOOKUP(C5,BOSS!$A$3:$B$1212,1,0) -> #N/A
A6: 02CMTK04 | B6: Kho Mới Tô Ký - Xóm Chợ - Hawonkoo | C6: DDH_202 | D6: Máy sấy bát Hawonkoo DDH-202 | E6: chiếc | F6: 1189552.4 | H6: =VLOOKUP(C6,JUNGER!$A$3:$B$7785,1,0) -> #N/A | I6: =VLOOKUP(C6,HWK!$A$3:$B$8917,1,0) -> #N/A | J6: =VLOOKUP(C6,CSSK!$A$3:$D$9887,1,0) -> #N/A | K6: =VLOOKUP(C6,BOSS!$A$3:$B$1212,1,0) -> #N/A
A7: 02CMTK04 | B7: Kho Mới Tô Ký - Xóm Chợ - Hawonkoo | C7: FAH_011 | D7: Quạt điện HAWONKOO FAH_011 | E7: chiếc | F7: 484008.56 | H7: =VLOOKUP(C7,JUNGER!$A$3:$B$7785,1,0) -> #N/A | I7: =VLOOKUP(C7,HWK!$A$3:$B$8917,1,0) -> #N/A | J7: =VLOOKUP(C7,CSSK!$A$3:$D$9887,1,0) -> #N/A | K7: =VLOOKUP(C7,BOSS!$A$3:$B$1212,1,0) -> #N/A
A8: 02CMTK04 | B8: Kho Mới Tô Ký - Xóm Chợ - Hawonkoo | C8: FAH0107WINGS_CF | D8: Quạt điện (cây) FAH0107WINGS - HAWONKOO - CF | E8: chiếc | F8: 514402.32 | H8: =VLOOKUP(C8,JUNGER!$A$3:$B$7785,1,0) -> #N/A | I8: =VLOOKUP(C8,HWK!$A$3:$B$8917,1,0) -> #N/A | J8: =VLOOKUP(C8,CSSK!$A$3:$D$9887,1,0) -> #N/A | K8: =VLOOKUP(C8,BOSS!$A$3:$B$1212,1,0) -> #N/A
A9: 02CMTK04 | B9: Kho Mới Tô Ký - Xóm Chợ - Hawonkoo | C9: FAH0107WINGS_GR | D9: Quạt điện (cây) FAH0107WINGS - HAWONKOO - GR | E9: chiếc | F9: 481985.04 | H9: =VLOOKUP(C9,JUNGER!$A$3:$B$7785,1,0) -> #N/A | I9: =VLOOKUP(C9,HWK!$A$3:$B$8917,1,0) -> #N/A | J9: =VLOOKUP(C9,CSSK!$A$3:$D$9887,1,0) -> #N/A | K9: =VLOOKUP(C9,BOSS!$A$3:$B$1212,1,0) -> #N/A
A10: 02CMTK04 | B10: Kho Mới Tô Ký - Xóm Chợ - Hawonkoo | C10: FDH012SPEED24_GR | D10: Quạt điện (cây) FDH012SPEED24- HAWONKOO - GR | E10: chiếc | F10: 675284.07 | H10: =VLOOKUP(C10,JUNGER!$A$3:$B$7785,1,0) -> #N/A | I10: =VLOOKUP(C10,HWK!$A$3:$B$8917,1,0) -> #N/A | J10: =VLOOKUP(C10,CSSK!$A$3:$D$9887,1,0) -> #N/A | K10: =VLOOKUP(C10,BOSS!$A$3:$B$1212,1,0) -> #N/A
A11: 02CMTK04 | B11: Kho Mới Tô Ký - Xóm Chợ - Hawonkoo | C11: PCH_500_CF | D11: Nồi áp suất Hawonkoo PCH-500-CF | E11: chiếc | F11: 1230036.9 | H11: =VLOOKUP(C11,JUNGER!$A$3:$B$7785,1,0) -> #N/A | I11: =VLOOKUP(C11,HWK!$A$3:$B$8917,1,0) -> #N/A | J11: =VLOOKUP(C11,CSSK!$A$3:$D$9887,1,0) -> #N/A | K11: =VLOOKUP(C11,BOSS!$A$3:$B$1212,1,0) -> #N/A
A12: 02CMTK04 | B12: Kho Mới Tô Ký - Xóm Chợ - Hawonkoo | C12: PCH_500_GR | D12: Nồi áp suất Hawonkoo PCH-500-GR | E12: chiếc | F12: 1230037.2 | H12: =VLOOKUP(C12,JUNGER!$A$3:$B$7785,1,0) -> #N/A | I12: =VLOOKUP(C12,HWK!$A$3:$B$8917,1,0) -> #N/A | J12: =VLOOKUP(C12,CSSK!$A$3:$D$9887,1,0) -> #N/A | K12: =VLOOKUP(C12,BOSS!$A$3:$B$1212,1,0) -> #N/A
A13: 02CMTK04 | B13: Kho Mới Tô Ký - Xóm Chợ - Hawonkoo | C13: PCH_500_PK | D13: Nồi áp suất Hawonkoo PCH-500-PK | E13: chiếc | F13: 1230036.9 | H13: =VLOOKUP(C13,JUNGER!$A$3:$B$7785,1,0) -> #N/A | I13: =VLOOKUP(C13,HWK!$A$3:$B$8917,1,0) -> #N/A | J13: =VLOOKUP(C13,CSSK!$A$3:$D$9887,1,0) -> #N/A | K13: =VLOOKUP(C13,BOSS!$A$3:$B$1212,1,0) -> #N/A
... A5395: ST_HCM04 | B5395: Massage Poongsan Sport HCM- street shop phạm Văn Đồng-12C và 12D Nguyên Hồng, P.1, Quận Gò Vấp | C5395: USH_400 | D5395: Máy sấy bát Hawonkoo USH-400 | E5395: chiếc | F5395: 1182993 | H5395: =VLOOKUP(C5395,JUNGER!$A$3:$B$7785,1,0) -> #N/A | I5395: =VLOOKUP(C5395,HWK!$A$3:$B$8917,1,0) -> #N/A | J5395: =VLOOKUP(C5395,CSSK!$A$3:$D$9887,1,0) -> #N/A | K5395: =VLOOKUP(C5395,BOSS!$A$3:$B$1212,1,0) -> #N/A
H5396: =VLOOKUP(C5396,JUNGER!$A$3:$B$7785,1,0) -> #N/A | I5396: =VLOOKUP(C5396,HWK!$A$3:$B$8917,1,0) -> #N/A | J5396: =VLOOKUP(C5396,CSSK!$A$3:$D$9887,1,0) -> #N/A | K5396: =VLOOKUP(C5396,BOSS!$A$3:$B$1212,1,0) -> #N/A
H5397: =VLOOKUP(C5397,JUNGER!$A$3:$B$7785,1,0) -> #N/A | I5397: =VLOOKUP(C5397,HWK!$A$3:$B$8917,1,0) -> #N/A | J5397: =VLOOKUP(C5397,CSSK!$A$3:$D$9887,1,0) -> #N/A | K5397: =VLOOKUP(C5397,BOSS!$A$3:$B$1212,1,0) -> #N/A
H5398: =VLOOKUP(C5398,JUNGER!$A$3:$B$7785,1,0) -> #N/A | I5398: =VLOOKUP(C5398,HWK!$A$3:$B$8917,1,0) -> #N/A | J5398: =VLOOKUP(C5398,CSSK!$A$3:$D$9887,1,0) -> #N/A | K5398: =VLOOKUP(C5398,BOSS!$A$3:$B$1212,1,0) -> #N/A
H5399: =VLOOKUP(C5399,JUNGER!$A$3:$B$7785,1,0) -> #N/A | I5399: =VLOOKUP(C5399,HWK!$A$3:$B$8917,1,0) -> #N/A | J5399: =VLOOKUP(C5399,CSSK!$A$3:$D$9887,1,0) -> #N/A | K5399: =VLOOKUP(C5399,BOSS!$A$3:$B$1212,1,0) -> #N/A
H5400: =VLOOKUP(C5400,JUNGER!$A$3:$B$7785,1,0) -> #N/A | I5400: =VLOOKUP(C5400,HWK!$A$3:$B$8917,1,0) -> #N/A | J5400: =VLOOKUP(C5400,CSSK!$A$3:$D$9887,1,0) -> #N/A | K5400: =VLOOKUP(C5400,BOSS!$A$3:$B$1212,1,0) -> #N/A

Sheet Sheet1
E1: m | F1: bep | G1: ha | H1: ms | I1: bo
E2: AFH_045 | F2: =VLOOKUP(E2,JUNGER!$A$3:$B$52,1,0) -> #N/A | G2: =VLOOKUP(E2,HWK!$A$3:$B$112,1,0) -> #N/A | H2: =VLOOKUP(E2,CSSK!$A$3:$C$96,1,0) -> #N/A | I2: =VLOOKUP(E2,BOSS!$A$3:$B$5,1,0) -> #N/A
E3: AFH_100 | F3: =VLOOKUP(E3,JUNGER!$A$3:$B$52,1,0) -> #N/A | G3: =VLOOKUP(E3,HWK!$A$3:$B$112,1,0) -> #N/A | H3: =VLOOKUP(E3,CSSK!$A$3:$C$96,1,0) -> #N/A | I3: =VLOOKUP(E3,BOSS!$A$3:$B$5,1,0) -> #N/A
E4: AFH_100_TQ | F4: =VLOOKUP(E4,JUNGER!$A$3:$B$52,1,0) -> #N/A | G4: =VLOOKUP(E4,HWK!$A$3:$B$112,1,0) -> #N/A | H4: =VLOOKUP(E4,CSSK!$A$3:$C$96,1,0) -> #N/A | I4: =VLOOKUP(E4,BOSS!$A$3:$B$5,1,0) -> #N/A
E5: AFH_101 | F5: =VLOOKUP(E5,JUNGER!$A$3:$B$52,1,0) -> #N/A | G5: =VLOOKUP(E5,HWK!$A$3:$B$112,1,0) -> #N/A | H5: =VLOOKUP(E5,CSSK!$A$3:$C$96,1,0) -> #N/A | I5: =VLOOKUP(E5,BOSS!$A$3:$B$5,1,0) -> #N/A
E6: AFH_101_TQ | F6: =VLOOKUP(E6,JUNGER!$A$3:$B$52,1,0) -> #N/A | G6: =VLOOKUP(E6,HWK!$A$3:$B$112,1,0) -> #N/A | H6: =VLOOKUP(E6,CSSK!$A$3:$C$96,1,0) -> #N/A | I6: =VLOOKUP(E6,BOSS!$A$3:$B$5,1,0) -> #N/A
E7: AFH_120_BA | F7: =VLOOKUP(E7,JUNGER!$A$3:$B$52,1,0) -> #N/A | G7: =VLOOKUP(E7,HWK!$A$3:$B$112,1,0) -> #N/A | H7: =VLOOKUP(E7,CSSK!$A$3:$C$96,1,0) -> #N/A | I7: =VLOOKUP(E7,BOSS!$A$3:$B$5,1,0) -> #N/A
E8: AFH_120_CF | F8: =VLOOKUP(E8,JUNGER!$A$3:$B$52,1,0) -> #N/A | G8: =VLOOKUP(E8,HWK!$A$3:$B$112,1,0) -> #N/A | H8: =VLOOKUP(E8,CSSK!$A$3:$C$96,1,0) -> #N/A | I8: =VLOOKUP(E8,BOSS!$A$3:$B$5,1,0) -> #N/A
E9: AFH_120_GR | F9: =VLOOKUP(E9,JUNGER!$A$3:$B$52,1,0) -> #N/A | G9: =VLOOKUP(E9,HWK!$A$3:$B$112,1,0) -> #N/A | H9: =VLOOKUP(E9,CSSK!$A$3:$C$96,1,0) -> #N/A | I9: =VLOOKUP(E9,BOSS!$A$3:$B$5,1,0) -> #N/A
E10: AFH_120_W | F10: =VLOOKUP(E10,JUNGER!$A$3:$B$52,1,0) -> #N/A | G10: =VLOOKUP(E10,HWK!$A$3:$B$112,1,0) -> #N/A | H10: =VLOOKUP(E10,CSSK!$A$3:$C$96,1,0) -> #N/A | I10: =VLOOKUP(E10,BOSS!$A$3:$B$5,1,0) -> #N/A
E11: AFH_128_W | F11: =VLOOKUP(E11,JUNGER!$A$3:$B$52,1,0) -> #N/A | G11: =VLOOKUP(E11,HWK!$A$3:$B$112,1,0) -> #N/A | H11: =VLOOKUP(E11,CSSK!$A$3:$C$96,1,0) -> #N/A | I11: =VLOOKUP(E11,BOSS!$A$3:$B$5,1,0) -> #N/A
E12: AFH_180_CF | F12: =VLOOKUP(E12,JUNGER!$A$3:$B$52,1,0) -> #N/A | G12: =VLOOKUP(E12,HWK!$A$3:$B$112,1,0) -> #N/A | H12: =VLOOKUP(E12,CSSK!$A$3:$C$96,1,0) -> #N/A | I12: =VLOOKUP(E12,BOSS!$A$3:$B$5,1,0) -> #N/A
E13: AFH_180_GR | F13: =VLOOKUP(E13,JUNGER!$A$3:$B$52,1,0) -> #N/A | G13: =VLOOKUP(E13,HWK!$A$3:$B$112,1,0) -> #N/A | H13: =VLOOKUP(E13,CSSK!$A$3:$C$96,1,0) -> #N/A | I13: =VLOOKUP(E13,BOSS!$A$3:$B$5,1,0) -> #N/A
... E233: TK017 | F233: =VLOOKUP(E233,JUNGER!$A$3:$B$52,1,0) -> #N/A | G233: =VLOOKUP(E233,HWK!$A$3:$B$112,1,0) -> #N/A | H233: =VLOOKUP(E233,CSSK!$A$3:$C$96,1,0) -> #N/A | I233: =VLOOKUP(E233,BOSS!$A$3:$B$5,1,0) -> #N/A
